<?xml version="1.0" ?>
<!-- =================================================================================== -->
<!-- |    This document was autogenerated by xacro from /smart_grasping_sandbox/src/smart_grasping_sandbox/fh_desc/robots/right_H1_ur5.urdf | -->
<!-- |    EDITING THIS FILE BY HAND IS NOT RECOMMENDED                                 | -->
<!-- =================================================================================== -->
<robot name="smart_grasping_sandbox" xmlns:xacro="http://ros.org/wiki/xacro">

  <!-- Colors -->
  <material name="DarkGrey">
    <color rgba="0.2 0.2 0.2 1.0"/>
  </material>
  <material name="Grey">
    <color rgba="0.4 0.4 0.4 1.0"/>
  </material>
  <material name="Orange">
    <color rgba="1.0 0.423529411765 0.0392156862745 1.0"/>
  </material>
  <material name="Blue">
    <color rgba="0 0.1 1.0 1.0"/>
  </material>
  <material name="LightGrey">
    <color rgba="0.7 0.7 0.7 1.0"/>
  </material>
  <material name="Red">
    <color rgba="0.9 0 0.2 1.0"/>
  </material>
  <material name="Green">
    <color rgba="0 0.9 0.5 1.0"/>
  </material>
  <material name="Yellow">
    <color rgba="0.7 0.7 0 1.0"/>
  </material>
  <material name="LightBlue">
    <color rgba="0. 0.3 1.0 1.0"/>
  </material>
  <material name="Black">
    <color rgba="0.05 0.05 0.05 1.0"/>
  </material>
  <material name="White">
    <color rgba="1.0 1.0 1.0 1.0" />
  </material>
  <material name="TacTipWhite">
   <color rgba="0.8 0.8 0.8 1.0"/>
 </material>
  <material name="TacTipBlack">
   <color rgba="0.1 0.1 0.1 1.0"/>
 </material>
 <material name="TransparentRed">
   <color rgba="0.9 0 0.2 0.5"/>
 </material>

<!-- ====================== Shadow Modular Grasper ====================== -->

<!-- connect hand to world -->
<link name="world"/>

<link name="SMG_base_link">
  <inertial>
    <origin rpy="0 0 0" xyz="-8.6116E-06 -0.0058125 0.028294"/>
    <mass value="0.07527"/>
    <inertia ixx="0.00014442" ixy="1.2033E-08" ixz="-5.9646E-10" iyy="0.00014979" iyz="-1.0288E-05" izz="5.2943E-05"/>
  </inertial>

  <visual>
    <origin rpy="0 0 0" xyz="0 0 0"/>
    <geometry>
      <mesh filename="hand/palm_link.stl"/>
    </geometry>
    <material name="DarkGrey"/>
  </visual>

  <collision>
    <origin rpy="0 0 0" xyz="0 0 0"/>
    <geometry>
      <mesh filename="hand/palm_link_col.stl"/>
    </geometry>
  </collision>
</link>

<joint name="SMG_base_joint" type="fixed">
  <origin rpy="0 0 0" xyz="0 0 -0.0005"/>
  <parent link="world"/>
  <child link="SMG_base_link"/>
</joint>

<!-- ============= SMG Body =============== -->
<link name="SMG_insert_F1"/>
<joint name="SMG_dummy_joint_1" type="fixed">
  <origin xyz="-0.045 -0.025981 0" rpy="0 0 2.3562" />
  <axis xyz="0 -1 0" />
  <parent link="SMG_base_link"/>
  <child link="SMG_insert_F1"/>
</joint>

<link name="SMG_insert_F2"/>
<joint name="SMG_dummy_joint_2" type="fixed">
  <origin xyz="0 0.029019 0" rpy="0 0 0" />
  <axis xyz="0 -1 0" />
  <parent link="SMG_base_link"/>
  <child link="SMG_insert_F2"/>
</joint>

<link name="SMG_insert_F3"/>

<joint name="SMG_dummy_joint_3" type="fixed">
  <origin xyz="0.045 -0.025981 0" rpy="0 0 -2.3562" />
  <axis xyz="0 -1 0" />
  <parent link="SMG_base_link"/>
  <child link="SMG_insert_F3"/>
</joint>

  <!-- ============= Finger 1 =============== -->

  <link name="SMG_F1_palm_link">
    <inertial>
        <origin xyz="-0.00681802120880393 -0.00947020456878004 0.067587996682422" rpy="0 0 0"/>
        <mass value="0.095"/>
        <inertia ixx="2.79747833772125E-05" ixy="-5.50900644725373E-08" ixz="-2.82072424927723E-07"
                 iyy="2.67800858812928E-05" iyz="3.1953125069394E-06" izz="9.86122271726361E-06"/>
    </inertial>
    <visual>
      <origin rpy="0 0 0" xyz="0 0 0"/>
      <geometry>
        <mesh filename="hand/finger_palm_link.stl"/>
      </geometry>
      <material name="DarkGrey"/>
    </visual>
    <!-- Collision part of palm_link_col.stl -->
  </link>


  <link name="SMG_F1_base_link">
    <inertial>
      <origin xyz="-0.00027 0.02711 0.06013" rpy="0 0 0" />
      <mass value="0.416" />
      <inertia ixx="0.00226490263" ixy="3.77717E-06" ixz="5.80703E-06"
               iyy="0.00193941498" iyz="6.9931504E-04" izz="0.00053136647" />
    </inertial>
    <visual>
      <origin rpy="0 0 0" xyz="0 0 0"/>
      <geometry>
        <mesh filename="hand/finger_base_link.stl"/>
      </geometry>
      <material name="DarkGrey"/>
    </visual>
    <collision>
      <origin rpy="0 0 0" xyz="0 0 0"/>
      <geometry>
        <mesh filename="hand/finger_base_link_col.stl"/>
      </geometry>
    </collision>
  </link>

  <link name="SMG_F1_link_1">
    <inertial>
      <origin xyz="-0.00071 -0.00022 0.01415" rpy="0 0 0" />
      <mass value="0.254" />
      <inertia ixx="0.00019133634" ixy="-0.00000008786" ixz="-0.00000720119"
               iyy="0.00021397597" iyz="-0.00000201648" izz="0.00008396436" />
    </inertial>
    <visual>
      <origin rpy="0 0 0" xyz="0 0 0"/>
      <geometry>
        <mesh filename="hand/finger_prox_link.stl"/>
      </geometry>
      <material name="LightGrey"/>
    </visual>
    <collision>
      <origin rpy="0 0 0" xyz="0 0 0"/>
      <geometry>
        <mesh filename="hand/finger_prox_link_col.stl"/>
      </geometry>
    </collision>
  </link>

  <link name="SMG_F1_link_2">
    <inertial>
        <origin xyz="0.00197 -0.00166 0.00962" rpy="0 0 0" />
        <mass value="0.071" />
        <inertia ixx="0.0000351756" ixy="0.0000000072" ixz="0.00000014613"
                 iyy="0.00003639824" iyz="-0.00000538058" izz="0.00001224172" />
    </inertial>
    <visual>
      <origin rpy="0 0 0" xyz="0 0 0"/>
      <geometry>
        <mesh filename="hand/finger_dist_link.stl"/>
      </geometry>
      <material name="DarkGrey"/>
    </visual>

    <collision>
      <origin rpy="0 0 0" xyz="0 0 0"/>
      <geometry>
        <mesh filename="hand/finger_dist_link.stl"/>
      </geometry>
    </collision>
  </link>

  <joint name="SMG_F1_palm" type="fixed">
    <origin rpy="0 0 0" xyz="0 0 0"/>
    <parent link="SMG_insert_F1"/>
    <child link="SMG_F1_palm_link"/>
  </joint>

  <joint name="SMG_F1J1" type="revolute">
    <origin xyz="0 0 0.00016528" rpy="-8.8818E-16 -1.0061E-16 0.022402" />
    <axis xyz="0 0 1"/>
    <parent link="SMG_F1_palm_link"/>
    <child link="SMG_F1_base_link"/>
    <limit lower="-3.14159265/4" upper="3.14159265/4" effort="2" velocity="1.0" />
    <dynamics damping="0.01"/>
  </joint>

  <joint name="SMG_F1J2" type="revolute">
    <origin xyz="0 0.035 0.11683" rpy="0.070695 6.9389E-16 2.0947E-16" />
    <axis xyz="1 0 0"/>
    <parent link="SMG_F1_base_link"/>
    <child link="SMG_F1_link_1"/>
    <limit lower="-3.14159265*80/180" upper="3.14159265/3" effort="2" velocity="1.0" />
    <dynamics damping="0.1"/>
  </joint>

  <joint name="SMG_F1J3" type="revolute">
    <origin xyz="0 0 0.06" rpy="-0.0068649 1.7347E-18 1.6176E-16" />
    <axis xyz="1 0 0"/>
    <parent link="SMG_F1_link_1"/>
    <child link="SMG_F1_link_2"/>
    <limit lower="-3.14159265/3" upper="3.14159265*80/180" effort="2" velocity="1.0" />
    <dynamics damping="0.01"/>
  </joint>

  <link name="SMG_F1_tactip_body">
    <inertial>
      <origin rpy="0 0 0" xyz="-0.000925580990320645 -0.00495543398528436 0.0355865585792753"/>
      <mass value="0.05"/>
      <inertia ixx="1E-06" ixy="0" ixz="0" iyy="1E-06" iyz="0" izz="1E-06"/>
    </inertial>

    <visual>
      <origin rpy="0 0 0" xyz="0 0 0"/>
      <geometry>
        <mesh filename="tip/minitip_smg_adapter.obj"/>
      </geometry>
      <material name="TacTipWhite"/>
    </visual>

    <collision>
      <origin rpy="0 0 0" xyz="0 0 0"/>
      <geometry>
        <mesh filename="tip/minitip_smg_adapter.obj"/>
      </geometry>
    </collision>
  </link>

  <joint name="SMG_F1_tactip_body_joint" type="fixed">
    <parent link="SMG_F1_link_2"/>
    <child link="SMG_F1_tactip_body"/>
  </joint>

  <link name="SMG_F1_tactip_tip">
    <inertial>
      <origin rpy="0 0 0" xyz="-0.000925580990320645 -0.00495543398528436 0.0355865585792753"/>
      <mass value="0.01"/>
      <inertia ixx="1E-06" ixy="0" ixz="0" iyy="1E-06" iyz="0" izz="1E-06"/>
    </inertial>

    <visual>
      <origin rpy="0 0 0" xyz="0 0 0"/>
      <geometry>
        <mesh filename="tip/smg_tactip_skin.obj"/>
      </geometry>
      <material name="Black"/>
    </visual>

    <collision>
      <origin rpy="0 0 0" xyz="0 0 0"/>
      <!-- <geometry>
        <mesh filename="tip/smg_tactip_core.obj"/>
      </geometry> -->
      <geometry>
        <sphere radius="0.02"/>
      </geometry>
    </collision>
  </link>

  <joint name="SMG_F1_tactip_tip_joint" type="fixed">
    <parent link="SMG_F1_tactip_body"/>
    <child link="SMG_F1_tactip_tip"/>
    <origin rpy="1.57 0 0" xyz="0.0 -0.0125 0.0575"/>
  </joint>

  <!-- TCP -->
  <link name="F1_tcp_link">
    <visual>
      <origin rpy="0 0 0" xyz="0 0 0"/>
      <geometry>
        <sphere radius="0.001"/>
      </geometry>
       <material name="TransparentRed"/>
    </visual>
    <inertial>
      <mass value="0.0"/>
      <origin rpy="0.0 0.0 0.0" xyz="0.0 0.0 0.0"/>
      <inertia ixx="1.0" ixy="0.0" ixz="0.0" iyy="1.0" iyz="0.0" izz="1.0"/>
    </inertial>
  </link>

  <joint name="F1_tcp_joint" type="fixed">
    <parent link="SMG_F1_tactip_body"/>
    <child link="F1_tcp_link"/>
    <origin rpy="1.57 0 0" xyz="0.0 -0.0325 0.0575"/>
  </joint>


  <!-- ============= Finger 2 =============== -->
  <link name="SMG_F2_palm_link">
      <inertial>
          <origin xyz="-0.00681802120880393 -0.00947020456878004 0.067587996682422" rpy="0 0 0"/>
          <mass value="0.095"/>
          <inertia ixx="2.79747833772125E-05" ixy="-5.50900644725373E-08" ixz="-2.82072424927723E-07"
                   iyy="2.67800858812928E-05" iyz="3.1953125069394E-06" izz="9.86122271726361E-06"/>
      </inertial>
      <visual>
        <origin rpy="0 0 0" xyz="0 0 0"/>
        <geometry>
          <mesh filename="hand/finger_palm_link.stl"/>
        </geometry>
        <material name="DarkGrey"/>
      </visual>
      <!-- Collision part of palm_link_col.stl -->
  </link>

  <link name="SMG_F2_base_link">
      <inertial>
        <origin xyz="-0.00027 0.02711 0.06013" rpy="0 0 0" />
        <mass value="0.416" />
        <inertia ixx="0.00226490263" ixy="3.77717E-06" ixz="5.80703E-06"
                 iyy="0.00193941498" iyz="6.9931504E-04" izz="0.00053136647" />
      </inertial>
      <visual>
        <origin rpy="0 0 0" xyz="0 0 0"/>
        <geometry>
          <mesh filename="hand/finger_base_link.stl"/>
        </geometry>
        <material name="DarkGrey"/>
      </visual>
      <collision>
        <origin rpy="0 0 0" xyz="0 0 0"/>
        <geometry>
          <mesh filename="hand/finger_base_link_col.stl"/>
        </geometry>
      </collision>
  </link>


  <link name="SMG_F2_link_1">
      <inertial>
        <origin xyz="-0.00071 -0.00022 0.01415" rpy="0 0 0" />
        <mass value="0.254" />
        <inertia ixx="0.00019133634" ixy="-0.00000008786" ixz="-0.00000720119"
                 iyy="0.00021397597" iyz="-0.00000201648" izz="0.00008396436" />
      </inertial>
      <visual>
        <origin rpy="0 0 0" xyz="0 0 0"/>
        <geometry>
          <mesh filename="hand/finger_prox_link.stl"/>
        </geometry>
        <material name="LightGrey"/>
      </visual>
      <collision>
        <origin rpy="0 0 0" xyz="0 0 0"/>
        <geometry>
          <mesh filename="hand/finger_prox_link_col.stl"/>
        </geometry>
      </collision>
  </link>


  <link name="SMG_F2_link_2">
      <inertial>
          <origin xyz="0.00197 -0.00166 0.00962" rpy="0 0 0" />
          <mass value="0.071" />
          <inertia ixx="0.0000351756" ixy="0.0000000072" ixz="0.00000014613"
                   iyy="0.00003639824" iyz="-0.00000538058" izz="0.00001224172" />
      </inertial>
      <visual>
        <origin rpy="0 0 0" xyz="0 0 0"/>
        <geometry>
          <mesh filename="hand/finger_dist_link.stl"/>
        </geometry>
        <material name="DarkGrey"/>
      </visual>

      <collision>
        <origin rpy="0 0 0" xyz="0 0 0"/>
        <geometry>
          <mesh filename="hand/finger_dist_link.stl"/>
        </geometry>
      </collision>
  </link>

  <joint name="SMG_F2_palm" type="fixed">
    <origin rpy="0 0 0" xyz="0 0 0"/>
    <parent link="SMG_insert_F2"/>
    <child link="SMG_F2_palm_link"/>
  </joint>

  <joint name="SMG_F2J1" type="revolute">
    <origin xyz="0 0 0.00016528" rpy="-8.8818E-16 -1.0061E-16 0.022402" />
    <axis xyz="0 0 1"/>
    <parent link="SMG_F2_palm_link"/>
    <child link="SMG_F2_base_link"/>
    <limit lower="-3.14159265/4" upper="3.14159265/4" effort="2" velocity="1.0" />
    <dynamics damping="0.01"/>
  </joint>

  <joint name="SMG_F2J2" type="revolute">
    <origin xyz="0 0.035 0.11683" rpy="0.070695 6.9389E-16 2.0947E-16" />
    <axis xyz="1 0 0"/>
    <parent link="SMG_F2_base_link"/>
    <child link="SMG_F2_link_1"/>
    <limit lower="-3.14159265*80/180" upper="3.14159265/3" effort="2" velocity="1.0" />
    <dynamics damping="0.1"/>
  </joint>

  <joint name="SMG_F2J3" type="revolute">
    <origin xyz="0 0 0.06" rpy="-0.0068649 1.7347E-18 1.6176E-16" />
    <axis xyz="1 0 0"/>
    <parent link="SMG_F2_link_1"/>
    <child link="SMG_F2_link_2"/>
    <limit lower="-3.14159265/3" upper="3.14159265*80/180" effort="2" velocity="1.0" />
    <dynamics damping="0.01"/>
  </joint>

  <link name="SMG_F2_tactip_body">
    <inertial>
      <origin rpy="0 0 0" xyz="-0.000925580990320645 -0.00495543398528436 0.0355865585792753"/>
      <mass value="0.05"/>
      <inertia ixx="1E-06" ixy="0" ixz="0" iyy="1E-06" iyz="0" izz="1E-06"/>
    </inertial>

    <visual>
      <origin rpy="0 0 0" xyz="0 0 0"/>
      <geometry>
        <mesh filename="tip/minitip_smg_adapter.obj"/>
      </geometry>
      <material name="TacTipWhite"/>
    </visual>

    <collision>
      <origin rpy="0 0 0" xyz="0 0 0"/>
      <geometry>
        <mesh filename="tip/minitip_smg_adapter.obj"/>
      </geometry>
    </collision>
  </link>

  <joint name="SMG_F2_tactip_body_joint" type="fixed">
    <parent link="SMG_F2_link_2"/>
    <child link="SMG_F2_tactip_body"/>
  </joint>

  <link name="SMG_F2_tactip_tip">
    <inertial>
      <origin rpy="0 0 0" xyz="-0.000925580990320645 -0.00495543398528436 0.0355865585792753"/>
      <mass value="0.01"/>
      <inertia ixx="1E-06" ixy="0" ixz="0" iyy="1E-06" iyz="0" izz="1E-06"/>
    </inertial>

    <visual>
      <origin rpy="0 0 0" xyz="0 0 0"/>
      <geometry>
        <mesh filename="tip/smg_tactip_skin.obj"/>
      </geometry>
      <material name="Black"/>
    </visual>

    <collision>
      <origin rpy="0 0 0" xyz="0 0 0"/>
      <!-- <geometry>
        <mesh filename="tip/smg_tactip_core.obj"/>
      </geometry> -->
      <geometry>
        <sphere radius="0.02"/>
      </geometry>
    </collision>
  </link>

  <joint name="SMG_F2_tactip_tip_joint" type="fixed">
    <parent link="SMG_F2_tactip_body"/>
    <child link="SMG_F2_tactip_tip"/>
    <origin rpy="1.57 0 0" xyz="0.0 -0.0125 0.0575"/>
  </joint>

  <!-- TCP -->
  <link name="F2_tcp_link">
    <visual>
      <origin rpy="0 0 0" xyz="0 0 0"/>
      <geometry>
        <sphere radius="0.001"/>
      </geometry>
       <material name="TransparentRed"/>
    </visual>
    <inertial>
      <mass value="0.0"/>
      <origin rpy="0.0 0.0 0.0" xyz="0.0 0.0 0.0"/>
      <inertia ixx="1.0" ixy="0.0" ixz="0.0" iyy="1.0" iyz="0.0" izz="1.0"/>
    </inertial>
  </link>

  <joint name="F2_tcp_joint" type="fixed">
    <parent link="SMG_F2_tactip_body"/>
    <child link="F2_tcp_link"/>
    <origin rpy="1.57 0 0" xyz="0.0 -0.0325 0.0575"/>
  </joint>

  <!-- ============= Finger 3 =============== -->
  <link name="SMG_F3_palm_link">
      <inertial>
          <origin xyz="-0.00681802120880393 -0.00947020456878004 0.067587996682422" rpy="0 0 0"/>
          <mass value="0.095"/>
          <inertia ixx="2.79747833772125E-05" ixy="-5.50900644725373E-08" ixz="-2.82072424927723E-07"
                   iyy="2.67800858812928E-05" iyz="3.1953125069394E-06" izz="9.86122271726361E-06"/>
      </inertial>
      <visual>
        <origin rpy="0 0 0" xyz="0 0 0"/>
        <geometry>
          <mesh filename="hand/finger_palm_link.stl"/>
        </geometry>
        <material name="DarkGrey"/>
      </visual>
      <!-- Collision part of palm_link_col.stl -->
  </link>


  <link name="SMG_F3_base_link">
      <inertial>
        <origin xyz="-0.00027 0.02711 0.06013" rpy="0 0 0" />
        <mass value="0.416" />
        <inertia ixx="0.00226490263" ixy="3.77717E-06" ixz="5.80703E-06"
                 iyy="0.00193941498" iyz="6.9931504E-04" izz="0.00053136647" />
      </inertial>
      <visual>
        <origin rpy="0 0 0" xyz="0 0 0"/>
        <geometry>
          <mesh filename="hand/finger_base_link.stl"/>
        </geometry>
        <material name="DarkGrey"/>
      </visual>
      <collision>
        <origin rpy="0 0 0" xyz="0 0 0"/>
        <geometry>
          <mesh filename="hand/finger_base_link_col.stl"/>
        </geometry>
      </collision>
  </link>


  <link name="SMG_F3_link_1">
      <inertial>
        <origin xyz="-0.00071 -0.00022 0.01415" rpy="0 0 0" />
        <mass value="0.254" />
        <inertia ixx="0.00019133634" ixy="-0.00000008786" ixz="-0.00000720119"
                 iyy="0.00021397597" iyz="-0.00000201648" izz="0.00008396436" />
      </inertial>
      <visual>
        <origin rpy="0 0 0" xyz="0 0 0"/>
        <geometry>
          <mesh filename="hand/finger_prox_link.stl"/>
        </geometry>
        <material name="LightGrey"/>
      </visual>
      <collision>
        <origin rpy="0 0 0" xyz="0 0 0"/>
        <geometry>
          <mesh filename="hand/finger_prox_link_col.stl"/>
        </geometry>
      </collision>
  </link>



  <link name="SMG_F3_link_2">
      <inertial>
          <origin xyz="0.00197 -0.00166 0.00962" rpy="0 0 0" />
          <mass value="0.071" />
          <inertia ixx="0.0000351756" ixy="0.0000000072" ixz="0.00000014613"
                   iyy="0.00003639824" iyz="-0.00000538058" izz="0.00001224172" />
      </inertial>
      <visual>
        <origin rpy="0 0 0" xyz="0 0 0"/>
        <geometry>
          <mesh filename="hand/finger_dist_link.stl"/>
        </geometry>
        <material name="DarkGrey"/>
      </visual>

      <collision>
        <origin rpy="0 0 0" xyz="0 0 0"/>
        <geometry>
          <mesh filename="hand/finger_dist_link.stl"/>
        </geometry>
      </collision>
  </link>


  <joint name="SMG_F3Palm" type="fixed">
    <origin rpy="0 0 0" xyz="0 0 0"/>
    <parent link="SMG_insert_F3"/>
    <child link="SMG_F3_palm_link"/>
  </joint>

  <joint name="SMG_F3J1" type="revolute">
    <origin xyz="0 0 0.00016528" rpy="-8.8818E-16 -1.0061E-16 0.022402" />
    <axis xyz="0 0 1"/>
    <parent link="SMG_F3_palm_link"/>
    <child link="SMG_F3_base_link"/>
    <limit lower="-3.14159265/4" upper="3.14159265/4" effort="2" velocity="1.0" />
    <dynamics damping="0.01"/>
  </joint>

  <joint name="SMG_F3J2" type="revolute">
    <origin xyz="0 0.035 0.11683" rpy="0.070695 6.9389E-16 2.0947E-16" />
    <axis xyz="1 0 0"/>
    <parent link="SMG_F3_base_link"/>
    <child link="SMG_F3_link_1"/>
    <limit lower="-3.14159265*80/180" upper="3.14159265/3" effort="2" velocity="1.0" />
    <dynamics damping="0.1"/>
  </joint>

  <joint name="SMG_F3J3" type="revolute">
    <origin xyz="0 0 0.06" rpy="-0.0068649 1.7347E-18 1.6176E-16" />
    <axis xyz="1 0 0"/>
    <parent link="SMG_F3_link_1"/>
    <child link="SMG_F3_link_2"/>
    <limit lower="-3.14159265/3" upper="3.14159265*80/180" effort="2" velocity="1.0" />
    <dynamics damping="0.01"/>
  </joint>

  <link name="SMG_F3_tactip_body">
    <inertial>
      <origin rpy="0 0 0" xyz="-0.000925580990320645 -0.00495543398528436 0.0355865585792753"/>
      <mass value="0.05"/>
      <inertia ixx="1E-06" ixy="0" ixz="0" iyy="1E-06" iyz="0" izz="1E-06"/>
    </inertial>

    <visual>
      <origin rpy="0 0 0" xyz="0 0 0"/>
      <geometry>
        <mesh filename="tip/minitip_smg_adapter.obj"/>
      </geometry>
      <material name="TacTipWhite"/>
    </visual>

    <collision>
      <origin rpy="0 0 0" xyz="0 0 0"/>
      <geometry>
        <mesh filename="tip/minitip_smg_adapter.obj"/>
      </geometry>
    </collision>
  </link>

  <joint name="SMG_F3_tactip_body_joint" type="fixed">
    <parent link="SMG_F3_link_2"/>
    <child link="SMG_F3_tactip_body"/>
  </joint>

  <link name="SMG_F3_tactip_tip">
    <inertial>
      <origin rpy="0 0 0" xyz="-0.000925580990320645 -0.00495543398528436 0.0355865585792753"/>
      <mass value="0.01"/>
      <inertia ixx="1E-06" ixy="0" ixz="0" iyy="1E-06" iyz="0" izz="1E-06"/>
    </inertial>

    <visual>
      <origin rpy="0 0 0" xyz="0 0 0"/>
      <geometry>
        <mesh filename="tip/smg_tactip_skin.obj"/>
      </geometry>
      <material name="Black"/>
    </visual>

    <collision>
      <origin rpy="0 0 0" xyz="0 0 0"/>
      <!-- <geometry>
        <mesh filename="tip/smg_tactip_core.obj"/>
      </geometry> -->
      <geometry>
        <sphere radius="0.02"/>
      </geometry>
    </collision>
  </link>

  <joint name="SMG_F3_tactip_tip_joint" type="fixed">
    <parent link="SMG_F3_tactip_body"/>
    <child link="SMG_F3_tactip_tip"/>
    <origin rpy="1.57 0 0" xyz="0.0 -0.0125 0.0575"/>
  </joint>

  <!-- TCP -->
  <link name="F3_tcp_link">
    <visual>
      <origin rpy="0 0 0" xyz="0 0 0"/>
      <geometry>
        <sphere radius="0.001"/>
      </geometry>
       <material name="TransparentRed"/>
    </visual>
    <inertial>
      <mass value="0.0"/>
      <origin rpy="0.0 0.0 0.0" xyz="0.0 0.0 0.0"/>
      <inertia ixx="1.0" ixy="0.0" ixz="0.0" iyy="1.0" iyz="0.0" izz="1.0"/>
    </inertial>
  </link>

  <joint name="F3_tcp_joint" type="fixed">
    <parent link="SMG_F3_tactip_body"/>
    <child link="F3_tcp_link"/>
    <origin rpy="1.57 0 0" xyz="0.0 -0.0325 0.0575"/>
  </joint>


  <!-- Pivot Point -->
  <link name="pivot_point_link">
    <visual>
      <origin rpy="0 0 0" xyz="0 0 0"/>
      <geometry>
        <sphere radius="0.005"/>
      </geometry>
       <material name="Yellow"/>
    </visual>
    <inertial>
      <mass value="0.0"/>
      <origin rpy="0.0 0.0 0.0" xyz="0.0 0.0 0.0"/>
      <inertia ixx="1.0" ixy="0.0" ixz="0.0" iyy="1.0" iyz="0.0" izz="1.0"/>
    </inertial>
  </link>

  <joint name="pivot_point_joint" type="fixed">
    <parent link="SMG_base_link"/>
    <child link="pivot_point_link"/>
    <origin rpy="0.0 0.0 0.0" xyz="0.0 -0.016 0.25"/>
  </joint>


</robot>
