<?xml version="1.0" ?>
<!-- =================================================================================== -->
<!-- |    This document was autogenerated by xacro from allegro_hand_description_right.xacro | -->
<!-- |    EDITING THIS FILE BY HAND IS NOT RECOMMENDED                                 | -->
<!-- =================================================================================== -->
<robot name="allegro_hand_right" xmlns:xacro="http://www.ros.org/wiki/xacro">
  <!-- ======================== BASE PARAMS ========================= -->
  <!-- ======================== FINGER PARAMS ======================== -->
  <!-- full height from joint to tip. when used,
    the radius of the finger tip sphere will be subtracted
    and one fixed link will be added for the tip. -->
  <!-- ========================= THUMB PARAMS ========================= -->
  <!-- ========================= LIMITS ========================= -->
  <!-- ============================================================================= -->

  <!-- Colors -->
  <material name="DarkGrey">
    <color rgba="0.2 0.2 0.2 1.0"/>
  </material>
  <material name="Grey">
    <color rgba="0.4 0.4 0.4 1.0"/>
  </material>
  <material name="Orange">
    <color rgba="1.0 0.423529411765 0.0392156862745 1.0"/>
  </material>
  <material name="Blue">
    <color rgba="0 0.1 1.0 1.0"/>
  </material>
  <material name="LightGrey">
    <color rgba="0.7 0.7 0.7 1.0"/>
  </material>
  <material name="Red">
    <color rgba="0.9 0 0.2 1.0"/>
  </material>
  <material name="Green">
    <color rgba="0 0.9 0.5 1.0"/>
  </material>
  <material name="Yellow">
    <color rgba="0.7 0.7 0 1.0"/>
  </material>
  <material name="LightBlue">
    <color rgba="0. 0.3 1.0 1.0"/>
  </material>
  <material name="Black">
    <color rgba="0.05 0.05 0.05 1.0"/>
  </material>
  <material name="White">
    <color rgba="1.0 1.0 1.0 1.0" />
  </material>
  <material name="TacTipWhite">
   <color rgba="0.8 0.8 0.8 1.0"/>
 </material>
 <material name="TransparentRed">
   <color rgba="0.9 0 0.2 0.5"/>
 </material>


  <!-- <link name="world"/> -->

  <!-- BASE -->
  <link name="base_link">
    <visual>
      <geometry>
        <mesh filename="meshes/allegro/base_link.obj"/>
      </geometry>
      <origin rpy="0 0 0" xyz="0 0 0 "/>
      <material name="black">
        <color rgba="0.2 0.2 0.2 1"/>
      </material>
    </visual>
    <collision>
      <origin rpy="0 0 0" xyz="-0.009300 0 -0.0475"/>
      <geometry>
        <box size="0.0408 0.1130 0.095"/>
        <!-- <box size="0.01 0.01 0.01"/> -->
      </geometry>
    </collision>
    <inertial>
      <origin xyz="0 0 0.0475" rpy="0 0 0"/>
      <mass value="0.4154"/>
      <inertia ixx="1e-4" ixy="0.0" ixz="0.0" iyy="1e-4" iyz="0.0" izz="1e-4"/>
    </inertial>
  </link>
  <!-- ============================================================================= -->
  <!-- FINGERS -->
  <!-- RIGHT HAND due to which finger is number 0 -->
  <!-- for LEFT HAND switch the sign of the **offset_origin_y** and **finger_angle_r** parameters-->
  <!-- Finget [0] -->
  <link name="link_0.0">
    <visual>
      <geometry>
        <mesh filename="meshes/allegro/link_0.0.obj"/>
      </geometry>
      <material name="black"/>
    </visual>
    <collision>
      <geometry>
        <box size="0.0196 0.0275 0.0164"/>
      </geometry>
      <origin rpy="0 0 0" xyz="0 0 0.0082"/>
    </collision>
    <inertial>
      <mass value="0.0119" />
      <origin xyz="0 0 0" rpy="0 0 0"/>
      <inertia ixx="1.01666658333e-06" ixy="0.0" ixz="0.0"
               iyy="6.47677333333e-07" iyz="0.0"
               izz="1.01666658333e-06" />
    </inertial>
  </link>
  <joint name="joint_0.0" type="revolute">
    <axis xyz="0 0 1"/>
    <limit effort="10" lower="-0.47" upper="0.47" velocity="6.283"/>
    <parent link="base_link"/>
    <child link="link_0.0"/>
    <origin rpy="-0.08726646255 0 0" xyz="0 0.0435 -0.001542"/>
  </joint>
  <link name="link_1.0">
    <visual>
      <geometry>
        <mesh filename="meshes/allegro/link_1.0.obj"/>
      </geometry>
      <material name="black"/>
    </visual>
    <collision>
      <geometry>
        <box size="0.0196 0.0275 0.054"/>
      </geometry>
      <origin rpy="0 0 0" xyz="0 0 0.027"/>
    </collision>
    <inertial>
      <mass value="0.065" />
      <origin xyz="0 0 0" rpy="0 0 0"/>
      <inertia ixx="7.95654166667e-05" ixy="1.7199e-05" ixz="8.75875e-06"
               iyy="2.47088833333e-05" iyz="2.413125e-05"
               izz="7.95654166667e-05" />
    </inertial>
  </link>
  <joint name="joint_1.0" type="revolute">
    <limit effort="10" lower="-0.196" upper="1.61" velocity="6.283"/>
    <axis xyz="0 1 0"/>
    <parent link="link_0.0"/>
    <child link="link_1.0"/>
    <origin xyz="0 0 0.0164"/>
  </joint>
  <link name="link_2.0">
    <visual>
      <geometry>
        <mesh filename="meshes/allegro/link_2.0.obj"/>
      </geometry>
      <material name="black"/>
    </visual>
    <collision>
      <geometry>
        <box size="0.0196 0.0275 0.0384"/>
      </geometry>
      <origin rpy="0 0 0" xyz="0 0 0.0192"/>
    </collision>
    <inertial>
      <mass value="0.0355" />
      <origin xyz="0 0 0" rpy="0 0 0"/>
      <inertia ixx="2.63979183333e-05" ixy="6.67968e-06" ixz="4.783625e-06"
               iyy="1.34948516667e-05" iyz="9.372e-06"
               izz="2.63979183333e-05" />
    </inertial>
  </link>
  <joint name="joint_2.0" type="revolute">
    <axis xyz="0 1 0"/>
    <limit effort="10" lower="-0.174" upper="1.709" velocity="6.283"/>
    <parent link="link_1.0"/>
    <child link="link_2.0"/>
    <origin xyz="0 0 0.054"/>
  </joint>
  <link name="link_3.0">
    <visual>
      <geometry>
        <mesh filename="meshes/allegro/link_3.0.obj"/>
      </geometry>
      <material name="black"/>
    </visual>
    <collision>
      <geometry>
        <sphere radius="0.0001"/>
      </geometry>
      <origin rpy="0 0 0" xyz="0 0 0.01335"/>
    </collision>
    <inertial>
      <mass value="0.0096" />
      <origin xyz="0 0 0" rpy="0 0 0"/>
      <inertia ixx="4.701248e-06" ixy="1.255968e-06" ixz="1.2936e-06"
               iyy="3.649312e-06" iyz="1.7622e-06"
               izz="4.701248e-06" />
    </inertial>
  </link>
  <joint name="joint_3.0" type="revolute">
    <axis xyz="0 1 0"/>
    <limit effort="10" lower="-0.227" upper="1.618" velocity="6.283"/>
    <parent link="link_2.0"/>
    <child link="link_3.0"/>
    <origin xyz="0 0 0.0384"/>
  </joint>

  <!-- End Effector -->
  <link name="ee_link_3">
    <visual>
      <origin rpy="0 0 0" xyz="0 0 0"/>
      <geometry>
        <sphere radius="0.001"/>
      </geometry>
        <material name="Red"/>
    </visual>
    <collision>
      <geometry>
        <sphere radius="0.001"/>
      </geometry>
      <origin rpy="0 0 0" xyz="0.0 0 0"/>
    </collision>
    <inertial>
      <mass value="0.0"/>
      <origin rpy="-3.14 0.0 1.57" xyz="0.0 0.0 0.0"/>
      <inertia ixx="0.001" ixy="0.0" ixz="0.0" iyy="0.001" iyz="0.0" izz="0.001"/>
    </inertial>
  </link>

  <joint name="ee_joint_3" type="fixed">
    <parent link="link_3.0"/>
    <child link="ee_link_3"/>
    <origin rpy="1.57 3.14 0.0" xyz="0.0 0.0 0.0156"/>
  </joint>

  <!-- DigiTac -->
  <link name="digitac_body_link_3">
  <inertial>
      <origin
        xyz="0.0044483897843889 -0.0137570316187898 -1.33478473442024E-08+0.02"
        rpy="0 0 0" />
      <mass
        value="0.00791827593084163" />
      <inertia
        ixx="7.86145751817283E-07"
        ixy="-4.85149902505629E-09"
        ixz="4.89421524982813E-12"
        iyy="1.59818901807298E-06"
        iyz="-2.18755873901251E-12"
        izz="1.06961344577448E-06" />
    </inertial>
    <visual>
      <origin
        xyz="0 0 0.02"
        rpy="0 0 0" />
      <geometry>
        <mesh
          filename="digitac/standard_digitac/digitac_asmb/meshes/digitac_body.obj" />
      </geometry>
      <material
        name="body_color">
        <color
          rgba="0.0 0.0 0.0 1" />
      </material>
    </visual>
    <collision>
      <origin
        xyz="0 0 0.02"
        rpy="0 0 0" />
      <geometry>
        <mesh
          filename="digitac/standard_digitac/digitac_asmb/meshes/digitac_body.obj" />
      </geometry>
    </collision>
  </link>

  <joint name="digitac_ee_joint_3" type="fixed">
      <parent link="ee_link_3"/>
      <child link="digitac_body_link_3"/>
      <origin rpy="1.57 3.14 -1.57" xyz="0.009 -0.019 0.0"/>
  </joint>

      
  <link name="digitac_tip_link_3">
    <inertial>
      <origin
        xyz="1.95689617055233E-05 -0.00418318281817305 -0.00513072481258713-0.02"
        rpy="0 0 0" />
      <mass
        value="0.000211579321175967" />
      <inertia
        ixx="1.6421406108058E-08"
        ixy="-3.59682768116548E-11"
        ixz="8.26721658003392E-12"
        iyy="1.10821033019274E-08"
        iyz="-1.94916165896316E-10"
        izz="2.23470337659004E-08" />
    </inertial>
    <visual>
      <origin
        xyz="0 0 -0.02"
        rpy="0 0 0" />
      <geometry>
        <mesh
          filename="digitac/standard_digitac/digitac_asmb_hollow/meshes/digitac_core.obj" />
      </geometry>
      <material
        name="digitac_skin">
        <color
          rgba="1.0 1.0 1.0 1" />
      </material>
    </visual>
    <collision>
      <origin
        xyz="0 0 -0.02"
        rpy="0 0 0" />
      <geometry>
        <mesh
          filename="digitac/standard_digitac/digitac_asmb_hollow/meshes/digitac_core.obj" />
      </geometry>
    </collision>
  </link>

  <joint name="digitac_tip_to_body_3" type="fixed">
    <origin
      xyz="0 0 0"
      rpy="3.14159265358979 0 -1.5707963267949" />
    <parent
      link="digitac_body_link_3" />
    <child
      link="digitac_tip_link_3" />
    <axis
      xyz="0 0 0" />
  </joint>

  <!-- Link 3 TCP -->
  <link name="link_3_tcp">
    <visual>
      <origin rpy="0 0 0" xyz="0 0 0"/>
      <geometry>
        <sphere radius="0.005"/>
      </geometry>
       <material name="TransparentRed"/>
    </visual>
    <inertial>
      <mass value="0.0"/>
      <origin rpy="0.0 0.0 1.57" xyz="0.0 0.0 0.0"/>
      <inertia ixx="1.0" ixy="0.0" ixz="0.0" iyy="1.0" iyz="0.0" izz="1.0"/>
    </inertial>
  </link>

  <joint name="joint_3_tcp" type="fixed">
    <parent link="digitac_body_link_3"/>
    <child link="link_3_tcp"/>
    <origin rpy="1.57 0 -1.57" xyz="0.0007 0.0 0.031"/>
  </joint>

  <!-- Finger [4] -->
  <link name="link_4.0">
    <visual>
      <geometry>
        <mesh filename="meshes/allegro/link_0.0.obj"/>
      </geometry>
      <material name="black"/>
    </visual>
    <collision>
      <geometry>
        <box size="0.0196 0.0275 0.0164"/>
      </geometry>
      <origin rpy="0 0 0" xyz="0 0 0.0082"/>
    </collision>
    <inertial>
      <mass value="0.0119" />
      <origin xyz="0 0 0" rpy="0 0 0"/>
      <inertia ixx="1.01666658333e-06" ixy="0.0" ixz="0.0"
               iyy="6.47677333333e-07" iyz="0.0"
               izz="1.01666658333e-06" />
    </inertial>
  </link>
  <joint name="joint_4.0" type="revolute">
    <axis xyz="0 0 1"/>
    <limit effort="10" lower="-0.47" upper="0.47" velocity="6.283"/>
    <parent link="base_link"/>
    <child link="link_4.0"/>
    <origin rpy="0.0 0 0" xyz="0 0 0.0007"/>
  </joint>
  <link name="link_5.0">
    <visual>
      <geometry>
        <mesh filename="meshes/allegro/link_1.0.obj"/>
      </geometry>
      <material name="black"/>
    </visual>
    <collision>
      <geometry>
        <box size="0.0196 0.0275 0.054"/>
      </geometry>
      <origin rpy="0 0 0" xyz="0 0 0.027"/>
    </collision>
    <inertial>
      <mass value="0.065" />
      <origin xyz="0 0 0" rpy="0 0 0"/>
      <inertia ixx="7.95654166667e-05" ixy="1.7199e-05" ixz="8.75875e-06"
               iyy="2.47088833333e-05" iyz="2.413125e-05"
               izz="7.95654166667e-05" />
    </inertial>
  </link>
  <joint name="joint_5.0" type="revolute">
    <limit effort="10" lower="-0.196" upper="1.61" velocity="6.283"/>
    <axis xyz="0 1 0"/>
    <parent link="link_4.0"/>
    <child link="link_5.0"/>
    <origin xyz="0 0 0.0164"/>
  </joint>
  <link name="link_6.0">
    <visual>
      <geometry>
        <mesh filename="meshes/allegro/link_2.0.obj"/>
      </geometry>
      <material name="black"/>
    </visual>
    <collision>
      <geometry>
        <box size="0.0196 0.0275 0.0384"/>
      </geometry>
      <origin rpy="0 0 0" xyz="0 0 0.0192"/>
    </collision>
    <inertial>
      <mass value="0.0355" />
      <origin xyz="0 0 0" rpy="0 0 0"/>
      <inertia ixx="2.63979183333e-05" ixy="6.67968e-06" ixz="4.783625e-06"
               iyy="1.34948516667e-05" iyz="9.372e-06"
               izz="2.63979183333e-05" />
    </inertial>
  </link>
  <joint name="joint_6.0" type="revolute">
    <axis xyz="0 1 0"/>
    <limit effort="10" lower="-0.174" upper="1.709" velocity="6.283"/>
    <parent link="link_5.0"/>
    <child link="link_6.0"/>
    <origin xyz="0 0 0.054"/>
  </joint>
  <link name="link_7.0">
    <visual>
      <geometry>
        <mesh filename="meshes/allegro/link_3.0.obj"/>
      </geometry>
      <material name="black"/>
    </visual>
    <collision>
      <geometry>
        <sphere radius="0.0001"/>
      </geometry>
      <origin rpy="0 0 0" xyz="0 0 0.01335"/>
    </collision>
    <inertial>
      <mass value="0.0096" />
      <origin xyz="0 0 0" rpy="0 0 0"/>
      <inertia ixx="4.701248e-06" ixy="1.255968e-06" ixz="1.2936e-06"
               iyy="3.649312e-06" iyz="1.7622e-06"
               izz="4.701248e-06" />
    </inertial>
  </link>
  <joint name="joint_7.0" type="revolute">
    <axis xyz="0 1 0"/>
    <limit effort="10" lower="-0.227" upper="1.618" velocity="6.283"/>
    <parent link="link_6.0"/>
    <child link="link_7.0"/>
    <origin xyz="0 0 0.0384"/>
  </joint>

  <!-- End Effector -->
  <link name="ee_link_7">
    <visual>
      <origin rpy="0 0 0" xyz="0 0 0"/>
      <geometry>
        <sphere radius="0.001"/>
      </geometry>
        <material name="Red"/>
    </visual>
    <collision>
      <geometry>
        <sphere radius="0.001"/>
      </geometry>
      <origin rpy="0 0 0" xyz="0.0 0 0"/>
    </collision>
    <inertial>
      <mass value="0.0"/>
      <origin rpy="-3.14 0.0 1.57" xyz="0.0 0.0 0.0"/>
      <inertia ixx="0.001" ixy="0.0" ixz="0.0" iyy="0.001" iyz="0.0" izz="0.001"/>
    </inertial>
  </link>

  <joint name="ee_joint_7" type="fixed">
    <parent link="link_7.0"/>
    <child link="ee_link_7"/>
    <origin rpy="1.57 3.14 0.0" xyz="0.0 0.0 0.0156"/>
  </joint>

  <!-- DigiTac -->
  <link name="digitac_body_link_7">
  <inertial>
      <origin
        xyz="0.0044483897843889 -0.0137570316187898 -1.33478473442024E-08+0.02"
        rpy="0 0 0" />
      <mass
        value="0.00791827593084163" />
      <inertia
        ixx="7.86145751817283E-07"
        ixy="-4.85149902505629E-09"
        ixz="4.89421524982813E-12"
        iyy="1.59818901807298E-06"
        iyz="-2.18755873901251E-12"
        izz="1.06961344577448E-06" />
    </inertial>
    <visual>
      <origin
        xyz="0 0 0.02"
        rpy="0 0 0" />
      <geometry>
        <mesh
          filename="digitac/standard_digitac/digitac_asmb/meshes/digitac_body.obj" />
      </geometry>
      <material
        name="body_color">
        <color
          rgba="0.0 0.0 0.0 1" />
      </material>
    </visual>
    <collision>
      <origin
        xyz="0 0 0.02"
        rpy="0 0 0" />
      <geometry>
        <mesh
          filename="digitac/standard_digitac/digitac_asmb/meshes/digitac_body.obj" />
      </geometry>
    </collision>
  </link>

  <joint name="digitac_ee_joint_7" type="fixed">
      <parent link="ee_link_7"/>
      <child link="digitac_body_link_7"/>
      <origin rpy="1.57 3.14 -1.57" xyz="0.009 -0.019 0.0"/>
  </joint>

      
  <link name="digitac_tip_link_7">
    <inertial>
      <origin
        xyz="1.95689617055233E-05 -0.00418318281817305 -0.00513072481258713-0.02"
        rpy="0 0 0" />
      <mass
        value="0.000211579321175967" />
      <inertia
        ixx="1.6421406108058E-08"
        ixy="-3.59682768116548E-11"
        ixz="8.26721658003392E-12"
        iyy="1.10821033019274E-08"
        iyz="-1.94916165896316E-10"
        izz="2.23470337659004E-08" />
    </inertial>
    <visual>
      <origin
        xyz="0 0 -0.02"
        rpy="0 0 0" />
      <geometry>
        <mesh
          filename="digitac/standard_digitac/digitac_asmb_hollow/meshes/digitac_core.obj" />
      </geometry>
      <material
        name="digitac_skin">
        <color
          rgba="1.0 1.0 1.0 1" />
      </material>
    </visual>
    <collision>
      <origin
        xyz="0 0 -0.02"
        rpy="0 0 0" />
      <geometry>
        <mesh
          filename="digitac/standard_digitac/digitac_asmb_hollow/meshes/digitac_core.obj" />
      </geometry>
    </collision>
  </link>

  <joint name="digitac_tip_to_body_7" type="fixed">
    <origin
      xyz="0 0 0"
      rpy="3.14159265358979 0 -1.5707963267949" />
    <parent
      link="digitac_body_link_7" />
    <child
      link="digitac_tip_link_7" />
    <axis
      xyz="0 0 0" />
  </joint>

  <!-- Link 7 TCP -->
  <link name="link_7_tcp">
    <visual>
      <origin rpy="0 0 0" xyz="0 0 0"/>
      <geometry>
        <sphere radius="0.005"/>
      </geometry>
       <material name="TransparentRed"/>
    </visual>
    <inertial>
      <mass value="0.0"/>
      <origin rpy="0.0 0.0 1.57" xyz="0.0 0.0 0.0"/>
      <inertia ixx="1.0" ixy="0.0" ixz="0.0" iyy="1.0" iyz="0.0" izz="1.0"/>
    </inertial>
  </link>

  <joint name="joint_7_tcp" type="fixed">
    <parent link="digitac_body_link_7"/>
    <child link="link_7_tcp"/>
    <origin rpy="1.57 0 -1.57" xyz="0.0007 0.0 0.031"/>
  </joint>

  <!-- Finger [8]-->
  <link name="link_8.0">
    <visual>
      <geometry>
        <mesh filename="meshes/allegro/link_0.0.obj"/>
      </geometry>
      <material name="black"/>
    </visual>
    <collision>
      <geometry>
        <box size="0.0196 0.0275 0.0164"/>
      </geometry>
      <origin rpy="0 0 0" xyz="0 0 0.0082"/>
    </collision>
    <inertial>
      <mass value="0.0119" />
      <origin xyz="0 0 0" rpy="0 0 0"/>
      <inertia ixx="1.01666658333e-06" ixy="0.0" ixz="0.0"
               iyy="6.47677333333e-07" iyz="0.0"
               izz="1.01666658333e-06" />
    </inertial>
  </link>
  <joint name="joint_8.0" type="revolute">
    <axis xyz="0 0 1"/>
    <limit effort="10" lower="-0.47" upper="0.47" velocity="6.283"/>
    <parent link="base_link"/>
    <child link="link_8.0"/>
    <origin rpy="0.08726646255 0 0" xyz="0 -0.0435 -0.001542"/>
  </joint>
  <link name="link_9.0">
    <visual>
      <geometry>
        <mesh filename="meshes/allegro/link_1.0.obj"/>
      </geometry>
      <material name="black"/>
    </visual>
    <collision>
      <geometry>
        <box size="0.0196 0.0275 0.054"/>
      </geometry>
      <origin rpy="0 0 0" xyz="0 0 0.027"/>
    </collision>
    <inertial>
      <mass value="0.065" />
      <origin xyz="0 0 0" rpy="0 0 0"/>
      <inertia ixx="7.95654166667e-05" ixy="1.7199e-05" ixz="8.75875e-06"
               iyy="2.47088833333e-05" iyz="2.413125e-05"
               izz="7.95654166667e-05" />
    </inertial>
  </link>
  <joint name="joint_9.0" type="revolute">
    <limit effort="10" lower="-0.196" upper="1.61" velocity="6.283"/>
    <axis xyz="0 1 0"/>
    <parent link="link_8.0"/>
    <child link="link_9.0"/>
    <origin xyz="0 0 0.0164"/>
  </joint>
  <link name="link_10.0">
    <visual>
      <geometry>
        <mesh filename="meshes/allegro/link_2.0.obj"/>
      </geometry>
      <material name="black"/>
    </visual>
    <collision>
      <geometry>
        <box size="0.0196 0.0275 0.0384"/>
      </geometry>
      <origin rpy="0 0 0" xyz="0 0 0.0192"/>
    </collision>
    <inertial>
      <mass value="0.0355" />
      <origin xyz="0 0 0" rpy="0 0 0"/>
      <inertia ixx="2.63979183333e-05" ixy="6.67968e-06" ixz="4.783625e-06"
               iyy="1.34948516667e-05" iyz="9.372e-06"
               izz="2.63979183333e-05" />
    </inertial>
  </link>
  <joint name="joint_10.0" type="revolute">
    <axis xyz="0 1 0"/>
    <limit effort="10" lower="-0.174" upper="1.709" velocity="6.283"/>
    <parent link="link_9.0"/>
    <child link="link_10.0"/>
    <origin xyz="0 0 0.054"/>
  </joint>
  <link name="link_11.0">
    <visual>
      <geometry>
        <mesh filename="meshes/allegro/link_3.0.obj"/>
      </geometry>
      <material name="black"/>
    </visual>
    <collision>
      <geometry>
        <sphere radius="0.0001"/>
      </geometry>
      <origin rpy="0 0 0" xyz="0 0 0.01335"/>
    </collision>
    <inertial>
      <mass value="0.0096" />
      <origin xyz="0 0 0" rpy="0 0 0"/>
      <inertia ixx="4.701248e-06" ixy="1.255968e-06" ixz="1.2936e-06"
               iyy="3.649312e-06" iyz="1.7622e-06"
               izz="4.701248e-06" />
    </inertial>
  </link>
  <joint name="joint_11.0" type="revolute">
    <axis xyz="0 1 0"/>
    <limit effort="10" lower="-0.227" upper="1.618" velocity="6.283"/>
    <parent link="link_10.0"/>
    <child link="link_11.0"/>
    <origin xyz="0 0 0.0384"/>
  </joint>

  <!-- End effector -->
  <link name="ee_link_11">
    <visual>
      <origin rpy="0 0 0" xyz="0 0 0"/>
      <geometry>
        <sphere radius="0.001"/>
      </geometry>
        <material name="Red"/>
    </visual>
    <collision>
      <geometry>
        <sphere radius="0.001"/>
      </geometry>
      <origin rpy="0 0 0" xyz="0.0 0 0"/>
    </collision>
    <inertial>
      <mass value="0.0"/>
      <origin rpy="-3.14 0.0 1.57" xyz="0.0 0.0 0.0"/>
      <inertia ixx="0.001" ixy="0.0" ixz="0.0" iyy="0.001" iyz="0.0" izz="0.001"/>
    </inertial>
  </link>

  <joint name="ee_joint_11" type="fixed">
    <parent link="link_11.0"/>
    <child link="ee_link_11"/>
    <origin rpy="1.57 3.14 0.0" xyz="0.0 0.0 0.0156"/>
  </joint>

    <!-- DigiTac -->
  <link name="digitac_body_link_11">
  <inertial>
      <origin
        xyz="0.0044483897843889 -0.0137570316187898 -1.33478473442024E-08+0.02"
        rpy="0 0 0" />
      <mass
        value="0.00791827593084163" />
      <inertia
        ixx="7.86145751817283E-07"
        ixy="-4.85149902505629E-09"
        ixz="4.89421524982813E-12"
        iyy="1.59818901807298E-06"
        iyz="-2.18755873901251E-12"
        izz="1.06961344577448E-06" />
    </inertial>
    <visual>
      <origin
        xyz="0 0 0.02"
        rpy="0 0 0" />
      <geometry>
        <mesh
          filename="digitac/standard_digitac/digitac_asmb/meshes/digitac_body.obj" />
      </geometry>
      <material
        name="body_color">
        <color
          rgba="0.0 0.0 0.0 1" />
      </material>
    </visual>
    <collision>
      <origin
        xyz="0 0 0.02"
        rpy="0 0 0" />
      <geometry>
        <mesh
          filename="digitac/standard_digitac/digitac_asmb/meshes/digitac_body.obj" />
      </geometry>
    </collision>
  </link>

  <joint name="digitac_ee_joint_11" type="fixed">
      <parent link="ee_link_11"/>
      <child link="digitac_body_link_11"/>
      <origin rpy="1.57 3.14 -1.57" xyz="0.009 -0.019 0.0"/>
  </joint>

  <link name="digitac_tip_link_11">
    <inertial>
      <origin
        xyz="1.95689617055233E-05 -0.00418318281817305 -0.00513072481258713-0.02"
        rpy="0 0 0" />
      <mass
        value="0.000211579321175967" />
      <inertia
        ixx="1.6421406108058E-08"
        ixy="-3.59682768116548E-11"
        ixz="8.26721658003392E-12"
        iyy="1.10821033019274E-08"
        iyz="-1.94916165896316E-10"
        izz="2.23470337659004E-08" />
    </inertial>
    <visual>
      <origin
        xyz="0 0 -0.02"
        rpy="0 0 0" />
      <geometry>
        <mesh
          filename="digitac/standard_digitac/digitac_asmb_hollow/meshes/digitac_core.obj" />
      </geometry>
      <material
        name="digitac_skin">
        <color
          rgba="1.0 1.0 1.0 1" />
      </material>
    </visual>
    <collision>
      <origin
        xyz="0 0 -0.02"
        rpy="0 0 0" />
      <geometry>
        <mesh
          filename="digitac/standard_digitac/digitac_asmb_hollow/meshes/digitac_core.obj" />
      </geometry>
    </collision>
  </link>

  <joint name="digitac_tip_to_body_11" type="fixed">
    <origin
      xyz="0 0 0"
      rpy="3.14159265358979 0 -1.5707963267949" />
    <parent
      link="digitac_body_link_11" />
    <child
      link="digitac_tip_link_11" />
    <axis
      xyz="0 0 0" />
  </joint>


  <!-- Link 11 TCP -->
  <link name="link_11_tcp">
    <visual>
      <origin rpy="0 0 0" xyz="0 0 0"/>
      <geometry>
        <sphere radius="0.005"/>
      </geometry>
       <material name="TransparentRed"/>
    </visual>
    <inertial>
      <mass value="0.0"/>
      <origin rpy="0.0 0.0 1.57" xyz="0.0 0.0 0.0"/>
      <inertia ixx="1.0" ixy="0.0" ixz="0.0" iyy="1.0" iyz="0.0" izz="1.0"/>
    </inertial>
  </link>

  <joint name="joint_11_tcp" type="fixed">
    <parent link="digitac_body_link_11"/>
    <child link="link_11_tcp"/>
    <origin rpy="1.57 0 -1.57" xyz="0.0007 0.0 0.031"/>
  </joint>
  
  <!-- THUMB -->
  <link name="link_12.0">
    <visual>
      <geometry>
        <mesh filename="meshes/allegro/link_12.0_right.obj"/>
      </geometry>
      <material name="black">
        <color rgba=".2 .2 .2 1"/>
      </material>
      <origin rpy="0 0 0" xyz="0 0 0"/>
    </visual>
    <collision>
      <geometry>
        <box size="0.0358 0.034 0.0455"/>
      </geometry>
      <origin rpy="0 0 0" xyz="-0.0179 0.009 0.0145"/>
    </collision>
    <inertial>
      <mass value="0.0176" />
      <origin xyz="0 0 0" rpy="0 0 0"/>
      <inertia ixx="1.89273333333e-5" ixy="7.16716e-06" ixz="5.35568e-06"
               iyy="1.43008213333e-05" iyz="6.8068e-06"
               izz="1.89273333333e-05" />
    </inertial>
  </link>
  <joint name="joint_12.0" type="revolute">
    <axis xyz="-1 0 0"/>
    <limit effort="10" lower="0.263" upper="1.396" velocity="6.283"/>
    <parent link="base_link"/>
    <child link="link_12.0"/>
    <origin rpy="0 -1.65806278845 -1.5707963259" xyz="-0.0182 0.019333 -0.045987"/>
  </joint>
  <link name="link_13.0">
    <visual>
      <geometry>
        <mesh filename="meshes/allegro/link_13.0.obj"/>
      </geometry>
      <material name="black">
        <color rgba=".2 .2 .2 1"/>
      </material>
    </visual>
    <collision>
      <geometry>
        <box size="0.0196 0.0275 0.0177"/>
      </geometry>
      <origin rpy="0 0 0" xyz="0 0 0.00885"/>
    </collision>
    <inertial>
      <mass value="0.0119" />
      <origin xyz="0 0 0" rpy="0 0 0"/>
      <inertia ixx="4.24250866667e-06" ixy="1.032087e-06" ixz="1.603525e-06"
               iyy="4.52362633333e-06" iyz="1.44808125e-06"
               izz="4.24250866667e-06" />
    </inertial>
  </link>
  <joint name="joint_13.0" type="revolute">
    <axis xyz="0 0 1"/>
    <limit effort="10" lower="-0.105" upper="1.163" velocity="6.283"/>
    <parent link="link_12.0"/>
    <child link="link_13.0"/>
    <!-- RIGHT -->
    <origin xyz="-0.027 0.005 0.0399"/>
    <!-- LEFT -->
    <!-- <origin xyz="-0.027 -0.005 0.0399"/> -->
  </joint>
  <link name="link_14.0">
    <visual>
      <geometry>
        <mesh filename="meshes/allegro/link_14.0.obj"/>
      </geometry>
      <material name="black">
      </material>
    </visual>
    <collision>
      <geometry>
        <box size="0.0196 0.0275 0.0514"/>
      </geometry>
      <origin rpy="0 0 0" xyz="0 0 0.0257"/>
    </collision>
    <inertial>
      <mass value="0.038" />
      <origin xyz="0 0 0" rpy="0 0 0"/>
      <inertia ixx="4.30439933333e-05" ixy="9.57068e-06" ixz="5.1205e-06" iyy="1.44451933333e-05"
               iyz="1.342825e-05" izz="4.30439933333e-05" />
    </inertial>
  </link>
  <joint name="joint_14.0" type="revolute">
    <axis xyz="0 1 0"/>
    <limit effort="10" lower="-0.189" upper="1.644" velocity="6.283"/>
    <parent link="link_13.0"/>
    <child link="link_14.0"/>
    <origin xyz="0 0 0.0177"/>
  </joint>
  <link name="link_15.0">
    <visual>
      <geometry>
        <mesh filename="meshes/allegro/link_15.0.obj"/>
      </geometry>
      <material name="black">
      </material>
    </visual>
    <collision>
      <geometry>
        <sphere radius="0.0001"/>
      </geometry>
      <origin rpy="0 0 0" xyz="0 0 0.02115"/>
    </collision>
    <inertial>
      <mass value="0.0388" />
      <origin xyz="0 0 0" rpy="0 0 0"/>
      <inertia ixx="3.29223173333e-05" ixy="8.042076e-06" ixz="5.2283e-06"
               iyy="1.47493026667e-5" iyz="1.1283525e-5"
               izz="3.29223173333e-05" />
    </inertial>
  </link>
  <joint name="joint_15.0" type="revolute">
    <axis xyz="0 1 0"/>
    <limit effort="10" lower="-0.162" upper="1.719" velocity="6.283"/>
    <parent link="link_14.0"/>
    <child link="link_15.0"/>
    <origin xyz="0 0 0.0514"/>
  </joint>

  <!-- End Effector -->
  <link name="ee_link_15">
    <visual>
      <origin rpy="0 0 0" xyz="0 0 0"/>
      <geometry>
        <sphere radius="0.001"/>
      </geometry>
        <material name="Red"/>
    </visual>
    <collision>
      <geometry>
        <sphere radius="0.001"/>
      </geometry>
      <origin rpy="0 0 0" xyz="0.0 0 0"/>
    </collision>
    <inertial>
      <mass value="0.0"/>
      <origin rpy="-3.14 0.0 1.57" xyz="0.0 0.0 0.0"/>
      <inertia ixx="0.001" ixy="0.0" ixz="0.0" iyy="0.001" iyz="0.0" izz="0.001"/>
    </inertial>
  </link>

  <joint name="ee_joint_15" type="fixed">
    <parent link="link_15.0"/>
    <child link="ee_link_15"/>
    <origin rpy="1.57 3.14 0.0" xyz="0.0 0.0 0.0313"/>
  </joint>


  <!-- DigiTac -->
  <link name="digitac_body_link_15">
  <inertial>
      <origin
        xyz="0.0044483897843889 -0.0137570316187898 -1.33478473442024E-08+0.02"
        rpy="0 0 0" />
      <mass
        value="0.00791827593084163" />
      <inertia
        ixx="7.86145751817283E-07"
        ixy="-4.85149902505629E-09"
        ixz="4.89421524982813E-12"
        iyy="1.59818901807298E-06"
        iyz="-2.18755873901251E-12"
        izz="1.06961344577448E-06" />
    </inertial>
    <visual>
      <origin
        xyz="0 0 0.02"
        rpy="0 0 0" />
      <geometry>
        <mesh
          filename="digitac/standard_digitac/digitac_asmb/meshes/digitac_body.obj" />
      </geometry>
      <material
        name="body_color">
        <color
          rgba="0.0 0.0 0.0 1" />
      </material>
    </visual>
    <collision>
      <origin
        xyz="0 0 0.02"
        rpy="0 0 0" />
      <geometry>
        <mesh
          filename="digitac/standard_digitac/digitac_asmb/meshes/digitac_body.obj" />
      </geometry>
    </collision>
  </link>

    <joint name="digitac_ee_joint_15" type="fixed">
        <parent link="ee_link_15"/>
        <child link="digitac_body_link_15"/>
        <origin rpy="1.57 3.14 -1.57" xyz="0.009 -0.019 0.0"/>
    </joint>

      
  <link name="digitac_tip_link_15">
    <inertial>
      <origin
        xyz="1.95689617055233E-05 -0.00418318281817305 -0.00513072481258713-0.02"
        rpy="0 0 0" />
      <mass
        value="0.000211579321175967" />
      <inertia
        ixx="1.6421406108058E-08"
        ixy="-3.59682768116548E-11"
        ixz="8.26721658003392E-12"
        iyy="1.10821033019274E-08"
        iyz="-1.94916165896316E-10"
        izz="2.23470337659004E-08" />
    </inertial>
    <visual>
      <origin
        xyz="0 0 -0.02"
        rpy="0 0 0" />
      <geometry>
        <mesh
          filename="digitac/standard_digitac/digitac_asmb_hollow/meshes/digitac_core.obj" />
      </geometry>
      <material
        name="digitac_skin">
        <color
          rgba="1.0 1.0 1.0 1" />
      </material>
    </visual>
    <collision>
      <origin
        xyz="0 0 -0.02"
        rpy="0 0 0" />
      <geometry>
        <mesh
          filename="digitac/standard_digitac/digitac_asmb_hollow/meshes/digitac_core.obj" />
      </geometry>
    </collision>
  </link>

  <joint name="digitac_tip_to_body_15" type="fixed">
    <origin
      xyz="0 0 0"
      rpy="3.14159265358979 0 -1.5707963267949" />
    <parent
      link="digitac_body_link_15" />
    <child
      link="digitac_tip_link_15" />
    <axis
      xyz="0 0 0" />
  </joint>


  <!-- Link 15 TCP -->
  <link name="link_15_tcp">
    <visual>
      <origin rpy="0 0 0" xyz="0 0 0"/>
      <geometry>
        <sphere radius="0.005"/>
      </geometry>
       <material name="TransparentRed"/>
    </visual>
    <inertial>
      <mass value="0.0"/>
      <origin rpy="0.0 0.0 1.57" xyz="0.0 0.0 0.0"/>
      <inertia ixx="1.0" ixy="0.0" ixz="0.0" iyy="1.0" iyz="0.0" izz="1.0"/>
    </inertial>
  </link>

  <joint name="joint_15_tcp" type="fixed">
    <parent link="digitac_body_link_15"/>
    <child link="link_15_tcp"/>
    <origin rpy="1.57 0 -1.57" xyz="0.0007 0.0 0.031"/>
  </joint>


  <!-- Pivot Point -->
  <link name="pivot_point_link">
    <visual>
      <origin rpy="0 0 0" xyz="0 0 0"/>
      <geometry>
        <sphere radius="0.005"/>
      </geometry>
       <material name="Yellow"/>
    </visual>
    <inertial>
      <mass value="0.0"/>
      <origin rpy="0.0 0.0 0.0" xyz="0.0 0.0 0.0"/>
      <inertia ixx="1.0" ixy="0.0" ixz="0.0" iyy="1.0" iyz="0.0" izz="1.0"/>
    </inertial>
  </link>

  <joint name="pivot_point_joint" type="fixed">
    <parent link="base_link"/>
    <child link="pivot_point_link"/>
    <origin rpy="-1.57 0.0 -1.57" xyz="0.25 0.0 0.0"/>
  </joint>


  <!-- ============================================================================= -->
  <!-- THUMB MACRO -->
  <!-- END THUMB MACRO -->
  <!-- THREE FINGER MACRO -->
  <!-- [[END]] THREE FINGER MACRO -->
</robot>